2024-12-08 22:31:15,904 Pulling original dataset from WandB
Traceback (most recent call last):
  File "C:\Users\eelil\OneDrive\Desktop\Capstone\Machine_Learning_Analysis_of_Bank_Fraud\clean_data.py", line 74, in <module>
    clean_data()
  File "C:\Users\eelil\OneDrive\Desktop\Capstone\Machine_Learning_Analysis_of_Bank_Fraud\clean_data.py", line 22, in clean_data
    df = pd.read_parquet(artifact.file())
                         ^^^^^^^^^^^^^^^
  File "C:\Users\eelil\.conda\envs\Machine_Learning_Analysis_of_Bank_Fraud\Lib\site-packages\wandb\sdk\artifacts\_validators.py", line 100, in wrapper
    return method(self, *args, **kwargs)
           ^^^^^^^^^^^^^^^^^^^^^^^^^^^^^
  File "C:\Users\eelil\.conda\envs\Machine_Learning_Analysis_of_Bank_Fraud\Lib\site-packages\wandb\sdk\artifacts\artifact.py", line 1978, in file
    return self.get_entry(list(self.manifest.entries)[0]).download(root)
           ^^^^^^^^^^^^^^^^^^^^^^^^^^^^^^^^^^^^^^^^^^^^^^^^^^^^^^^^^^^^^
  File "C:\Users\eelil\.conda\envs\Machine_Learning_Analysis_of_Bank_Fraud\Lib\site-packages\wandb\sdk\artifacts\artifact_manifest_entry.py", line 159, in download
    md5_hash = md5_file_b64(dest_path)
               ^^^^^^^^^^^^^^^^^^^^^^^
  File "C:\Users\eelil\.conda\envs\Machine_Learning_Analysis_of_Bank_Fraud\Lib\site-packages\wandb\sdk\lib\hashutil.py", line 47, in md5_file_b64
    return _b64_from_hasher(_md5_file_hasher(*paths))
                            ^^^^^^^^^^^^^^^^^^^^^^^^
  File "C:\Users\eelil\.conda\envs\Machine_Learning_Analysis_of_Bank_Fraud\Lib\site-packages\wandb\sdk\lib\hashutil.py", line 64, in _md5_file_hasher
    with open(path, "rb") as f:
         ^^^^^^^^^^^^^^^^
OSError: [Errno 22] Invalid argument: '.\\artifacts\\credit_card_data:v0\\credit_card_transactions.csv'
