wandb: Downloading large artifact cleaned_credit_card_data:latest, 85.55MB. 1 files...
wandb:   1 of 1 files downloaded.
Done. 0:0:0.2
2024-12-11 07:37:54,480 Creating side df of unique city and state combinations
2024-12-11 07:37:54,506 Getting the geocoding file
2024-12-11 07:40:15,703 Retrying (Retry(total=1, connect=None, read=None, redirect=None, status=None)) after connection broken by 'ReadTimeoutError("HTTPSConnectionPool(host='nominatim.openstreetmap.org', port=443): Read timed out. (read timeout=1)")': /search?q=June+Lake%2C+CA&format=json&limit=1
2024-12-11 07:41:43,492 Retrying (Retry(total=1, connect=None, read=None, redirect=None, status=None)) after connection broken by 'ReadTimeoutError("HTTPSConnectionPool(host='nominatim.openstreetmap.org', port=443): Read timed out. (read timeout=1)")': /search?q=Muskegon%2C+MI&format=json&limit=1
2024-12-11 07:42:29,685 Retrying (Retry(total=1, connect=None, read=None, redirect=None, status=None)) after connection broken by 'ReadTimeoutError("HTTPSConnectionPool(host='nominatim.openstreetmap.org', port=443): Read timed out. (read timeout=1)")': /search?q=Murfreesboro%2C+TN&format=json&limit=1
2024-12-11 07:51:24,778 Retrying (Retry(total=1, connect=None, read=None, redirect=None, status=None)) after connection broken by 'ReadTimeoutError("HTTPSConnectionPool(host='nominatim.openstreetmap.org', port=443): Read timed out. (read timeout=1)")': /search?q=Chester+Heights%2C+PA&format=json&limit=1
2024-12-11 07:59:04,116 Uploading file to WandB.
Traceback (most recent call last):
  File "C:\Users\eelil\OneDrive\Desktop\Capstone\Machine_Learning_Analysis_of_Bank_Fraud\data\data_preparation\cust_loc_map.py", line 86, in <module>
    cust_loc_map()
  File "C:\Users\eelil\OneDrive\Desktop\Capstone\Machine_Learning_Analysis_of_Bank_Fraud\data\data_preparation\cust_loc_map.py", line 72, in cust_loc_map
    cust_loc.to_parquet(cust_loc_file, index=False)
  File "C:\Users\eelil\.conda\envs\Machine_Learning_Analysis_of_Bank_Fraud\Lib\site-packages\pandas\util\_decorators.py", line 333, in wrapper
    return func(*args, **kwargs)
           ^^^^^^^^^^^^^^^^^^^^^
  File "C:\Users\eelil\.conda\envs\Machine_Learning_Analysis_of_Bank_Fraud\Lib\site-packages\pandas\core\frame.py", line 3113, in to_parquet
    return to_parquet(
           ^^^^^^^^^^^
  File "C:\Users\eelil\.conda\envs\Machine_Learning_Analysis_of_Bank_Fraud\Lib\site-packages\pandas\io\parquet.py", line 480, in to_parquet
    impl.write(
  File "C:\Users\eelil\.conda\envs\Machine_Learning_Analysis_of_Bank_Fraud\Lib\site-packages\pandas\io\parquet.py", line 198, in write
    path_or_handle, handles, filesystem = _get_path_or_handle(
                                          ^^^^^^^^^^^^^^^^^^^^
  File "C:\Users\eelil\.conda\envs\Machine_Learning_Analysis_of_Bank_Fraud\Lib\site-packages\pandas\io\parquet.py", line 140, in _get_path_or_handle
    handles = get_handle(
              ^^^^^^^^^^^
  File "C:\Users\eelil\.conda\envs\Machine_Learning_Analysis_of_Bank_Fraud\Lib\site-packages\pandas\io\common.py", line 749, in get_handle
    check_parent_directory(str(handle))
  File "C:\Users\eelil\.conda\envs\Machine_Learning_Analysis_of_Bank_Fraud\Lib\site-packages\pandas\io\common.py", line 616, in check_parent_directory
    raise OSError(rf"Cannot save file into a non-existent directory: '{parent}'")
OSError: Cannot save file into a non-existent directory: 'data\data_preparation'
